  0%|          | 0/100000 [00:00<?, ?it/s]  0%|          | 1/100000 [00:00<25:32:57,  1.09it/s]  0%|          | 2/100000 [00:06<107:55:57,  3.89s/it]  0%|          | 3/100000 [00:10<105:55:27,  3.81s/it]  0%|          | 4/100000 [00:15<118:29:35,  4.27s/it]  0%|          | 5/100000 [00:19<120:00:22,  4.32s/it]  0%|          | 6/100000 [00:27<151:04:03,  5.44s/it]  0%|          | 7/100000 [01:13<514:37:46, 18.53s/it]  0%|          | 7/100000 [01:34<375:12:57, 13.51s/it]
ERROR:root:Internal Python error in the inspect module.
Below is the traceback from this internal error.

Traceback (most recent call last):
  File "/Users/anton/.conda/envs/reinforcement_learning/lib/python3.8/site-packages/IPython/core/interactiveshell.py", line 3418, in run_code
    exec(code_obj, self.user_global_ns, self.user_ns)
  File "<ipython-input-7-8f485f7f2afa>", line 11, in <module>
    agent.learn()
  File "../src/agent.py", line 116, in learn
    self.actor.optimizer.apply_gradients(zip(actor_gradient, self.actor.trainable_variables))
  File "/Users/anton/.conda/envs/reinforcement_learning/lib/python3.8/site-packages/tensorflow/python/keras/optimizer_v2/optimizer_v2.py", line 625, in apply_gradients
    apply_state = self._prepare(var_list)
  File "/Users/anton/.conda/envs/reinforcement_learning/lib/python3.8/site-packages/tensorflow/python/keras/optimizer_v2/optimizer_v2.py", line 872, in _prepare
    var_dtype = var.dtype.base_dtype
  File "/Users/anton/.conda/envs/reinforcement_learning/lib/python3.8/site-packages/tensorflow/python/framework/dtypes.py", line 87, in base_dtype
    if self._is_ref_dtype:
  File "/Users/anton/.conda/envs/reinforcement_learning/lib/python3.8/site-packages/tensorflow/python/framework/dtypes.py", line 74, in _is_ref_dtype
    return self._type_enum > 100
KeyboardInterrupt

During handling of the above exception, another exception occurred:

Traceback (most recent call last):
  File "/Users/anton/.conda/envs/reinforcement_learning/lib/python3.8/site-packages/IPython/core/interactiveshell.py", line 2045, in showtraceback
    stb = value._render_traceback_()
AttributeError: 'KeyboardInterrupt' object has no attribute '_render_traceback_'

During handling of the above exception, another exception occurred:

Traceback (most recent call last):
  File "/Users/anton/.conda/envs/reinforcement_learning/lib/python3.8/site-packages/IPython/core/ultratb.py", line 1170, in get_records
    return _fixed_getinnerframes(etb, number_of_lines_of_context, tb_offset)
  File "/Users/anton/.conda/envs/reinforcement_learning/lib/python3.8/site-packages/IPython/core/ultratb.py", line 316, in wrapped
    return f(*args, **kwargs)
  File "/Users/anton/.conda/envs/reinforcement_learning/lib/python3.8/site-packages/IPython/core/ultratb.py", line 350, in _fixed_getinnerframes
    records = fix_frame_records_filenames(inspect.getinnerframes(etb, context))
  File "/Users/anton/.conda/envs/reinforcement_learning/lib/python3.8/inspect.py", line 1503, in getinnerframes
    frameinfo = (tb.tb_frame,) + getframeinfo(tb, context)
  File "/Users/anton/.conda/envs/reinforcement_learning/lib/python3.8/inspect.py", line 1461, in getframeinfo
    filename = getsourcefile(frame) or getfile(frame)
  File "/Users/anton/.conda/envs/reinforcement_learning/lib/python3.8/inspect.py", line 708, in getsourcefile
    if getattr(getmodule(object, filename), '__loader__', None) is not None:
  File "/Users/anton/.conda/envs/reinforcement_learning/lib/python3.8/inspect.py", line 754, in getmodule
    os.path.realpath(f)] = module.__name__
  File "/Users/anton/.conda/envs/reinforcement_learning/lib/python3.8/posixpath.py", line 391, in realpath
    path, ok = _joinrealpath(filename[:0], filename, {})
  File "/Users/anton/.conda/envs/reinforcement_learning/lib/python3.8/posixpath.py", line 425, in _joinrealpath
    if not islink(newpath):
  File "/Users/anton/.conda/envs/reinforcement_learning/lib/python3.8/posixpath.py", line 167, in islink
    st = os.lstat(path)
KeyboardInterrupt
