loading weights
945736
3000
[1.07478544 0.93044417]
  0%|          | 0/250 [00:00<?, ?it/s]  0%|          | 1/250 [00:10<42:53, 10.34s/it]  1%|          | 2/250 [00:19<40:59,  9.92s/it]  1%|          | 3/250 [00:31<43:08, 10.48s/it]  2%|▏         | 4/250 [00:40<40:56,  9.98s/it]  2%|▏         | 5/250 [00:50<41:12, 10.09s/it]  2%|▏         | 6/250 [00:58<37:36,  9.25s/it]  2%|▏         | 6/250 [01:04<43:47, 10.77s/it]
ERROR:root:Internal Python error in the inspect module.
Below is the traceback from this internal error.

Traceback (most recent call last):
  File "/Users/anton/.conda/envs/reinforcement_learning/lib/python3.8/site-packages/IPython/core/interactiveshell.py", line 3418, in run_code
    exec(code_obj, self.user_global_ns, self.user_ns)
  File "<ipython-input-7-94bfbd7604e9>", line 11, in <module>
    agent.learn()
  File "../src/agent.py", line 130, in learn
    policy_actions = self.actor(states)
  File "/Users/anton/.conda/envs/reinforcement_learning/lib/python3.8/site-packages/tensorflow/python/keras/engine/base_layer.py", line 1012, in __call__
    outputs = call_fn(inputs, *args, **kwargs)
  File "../src/networks.py", line 51, in call
    return policy * self.upper_bound
  File "/Users/anton/.conda/envs/reinforcement_learning/lib/python3.8/site-packages/tensorflow/python/ops/math_ops.py", line 1164, in binary_op_wrapper
    return func(x, y, name=name)
  File "/Users/anton/.conda/envs/reinforcement_learning/lib/python3.8/site-packages/tensorflow/python/ops/math_ops.py", line 1496, in _mul_dispatch
    return multiply(x, y, name=name)
  File "/Users/anton/.conda/envs/reinforcement_learning/lib/python3.8/site-packages/tensorflow/python/util/dispatch.py", line 201, in wrapper
    return target(*args, **kwargs)
  File "/Users/anton/.conda/envs/reinforcement_learning/lib/python3.8/site-packages/tensorflow/python/ops/math_ops.py", line 518, in multiply
    return gen_math_ops.mul(x, y, name)
  File "/Users/anton/.conda/envs/reinforcement_learning/lib/python3.8/site-packages/tensorflow/python/ops/gen_math_ops.py", line 6072, in mul
    return mul_eager_fallback(
  File "/Users/anton/.conda/envs/reinforcement_learning/lib/python3.8/site-packages/tensorflow/python/ops/gen_math_ops.py", line 6099, in mul_eager_fallback
    _execute.record_gradient(
  File "/Users/anton/.conda/envs/reinforcement_learning/lib/python3.8/site-packages/tensorflow/python/eager/backprop.py", line 176, in _record_gradient
    ops.get_name_scope())
  File "/Users/anton/.conda/envs/reinforcement_learning/lib/python3.8/site-packages/tensorflow/python/framework/ops.py", line 6046, in get_name_scope
    return context.context().scope_name.rstrip("/")
KeyboardInterrupt

During handling of the above exception, another exception occurred:

Traceback (most recent call last):
  File "/Users/anton/.conda/envs/reinforcement_learning/lib/python3.8/site-packages/IPython/core/interactiveshell.py", line 2045, in showtraceback
    stb = value._render_traceback_()
AttributeError: 'KeyboardInterrupt' object has no attribute '_render_traceback_'

During handling of the above exception, another exception occurred:

Traceback (most recent call last):
  File "/Users/anton/.conda/envs/reinforcement_learning/lib/python3.8/site-packages/IPython/core/ultratb.py", line 1170, in get_records
    return _fixed_getinnerframes(etb, number_of_lines_of_context, tb_offset)
  File "/Users/anton/.conda/envs/reinforcement_learning/lib/python3.8/site-packages/IPython/core/ultratb.py", line 316, in wrapped
    return f(*args, **kwargs)
  File "/Users/anton/.conda/envs/reinforcement_learning/lib/python3.8/site-packages/IPython/core/ultratb.py", line 350, in _fixed_getinnerframes
    records = fix_frame_records_filenames(inspect.getinnerframes(etb, context))
  File "/Users/anton/.conda/envs/reinforcement_learning/lib/python3.8/inspect.py", line 1503, in getinnerframes
    frameinfo = (tb.tb_frame,) + getframeinfo(tb, context)
  File "/Users/anton/.conda/envs/reinforcement_learning/lib/python3.8/inspect.py", line 1461, in getframeinfo
    filename = getsourcefile(frame) or getfile(frame)
  File "/Users/anton/.conda/envs/reinforcement_learning/lib/python3.8/inspect.py", line 708, in getsourcefile
    if getattr(getmodule(object, filename), '__loader__', None) is not None:
  File "/Users/anton/.conda/envs/reinforcement_learning/lib/python3.8/inspect.py", line 751, in getmodule
    f = getabsfile(module)
  File "/Users/anton/.conda/envs/reinforcement_learning/lib/python3.8/inspect.py", line 720, in getabsfile
    _filename = getsourcefile(object) or getfile(object)
  File "/Users/anton/.conda/envs/reinforcement_learning/lib/python3.8/inspect.py", line 705, in getsourcefile
    if os.path.exists(filename):
  File "/Users/anton/.conda/envs/reinforcement_learning/lib/python3.8/genericpath.py", line 19, in exists
    os.stat(path)
KeyboardInterrupt
