2021-01-29 12:13:19,979 INFO    MainThread:4454 [wandb_setup.py:_flush():70] setting env: {}
2021-01-29 12:13:19,979 INFO    MainThread:4454 [wandb_setup.py:_flush():70] multiprocessing start_methods=spawn,fork,forkserver
2021-01-29 12:13:19,979 INFO    MainThread:4454 [wandb_setup.py:_flush():70] setting login settings: {}
2021-01-29 12:13:19,979 INFO    MainThread:4454 [wandb_setup.py:_flush():70] configuring jupyter hooks <wandb.sdk.wandb_init._WandbInit object at 0x7fd621ec3880>
2021-01-29 12:13:19,979 INFO    MainThread:4454 [wandb_init.py:_log_setup():303] Logging user logs to /Users/anton/Projects/reinforcement_learning/ppo/nbs/wandb/run-20210129_121319-353wkri4/logs/debug.log
2021-01-29 12:13:19,979 INFO    MainThread:4454 [wandb_init.py:_log_setup():304] Logging internal logs to /Users/anton/Projects/reinforcement_learning/ppo/nbs/wandb/run-20210129_121319-353wkri4/logs/debug-internal.log
2021-01-29 12:13:22,279 ERROR   MainThread:4454 [wandb_init.py:init():601] error
Traceback (most recent call last):
  File "/Users/anton/.conda/envs/reinforcement_learning/lib/python3.8/site-packages/wandb/sdk/wandb_init.py", line 575, in init
    run = wi.init()
  File "/Users/anton/.conda/envs/reinforcement_learning/lib/python3.8/site-packages/wandb/sdk/wandb_init.py", line 411, in init
    ret = backend.interface.communicate_run(run, timeout=30)
  File "/Users/anton/.conda/envs/reinforcement_learning/lib/python3.8/site-packages/wandb/sdk/interface/interface.py", line 541, in communicate_run
    run = self._make_run(run_obj)
  File "/Users/anton/.conda/envs/reinforcement_learning/lib/python3.8/site-packages/wandb/sdk/interface/interface.py", line 182, in _make_run
    run._make_proto_run(proto_run)
  File "/Users/anton/.conda/envs/reinforcement_learning/lib/python3.8/site-packages/wandb/sdk/wandb_run.py", line 315, in _make_proto_run
    run.job_type = self._job_type
TypeError: {'learning_rate': 0.0001, 'batch_size': 64, 'architecture': 'ppo', 'infra': 'Ubuntu'} has type dict, but expected one of: bytes, unicode
2021-01-29 12:13:31,046 INFO    MainThread:4454 [internal.py:handle_exit():138] Internal process exited
