loading weights
945736
3000
[1.07478544 0.93044417]
  0%|          | 0/250 [00:00<?, ?it/s]  0%|          | 1/250 [00:16<1:06:59, 16.14s/it]  1%|          | 2/250 [00:25<49:24, 11.96s/it]    1%|          | 3/250 [00:36<47:58, 11.65s/it]  2%|▏         | 4/250 [00:47<46:25, 11.32s/it]  2%|▏         | 5/250 [01:07<59:06, 14.48s/it]  2%|▏         | 6/250 [01:53<1:42:29, 25.20s/it]  2%|▏         | 6/250 [02:30<1:42:07, 25.11s/it]
ERROR:root:Internal Python error in the inspect module.
Below is the traceback from this internal error.

Traceback (most recent call last):
  File "/Users/anton/.conda/envs/reinforcement_learning/lib/python3.8/site-packages/IPython/core/interactiveshell.py", line 3418, in run_code
    exec(code_obj, self.user_global_ns, self.user_ns)
  File "<ipython-input-7-94bfbd7604e9>", line 11, in <module>
    agent.learn()
  File "../src/agent.py", line 109, in learn
    state, action, reward, new_state, done = self.replay_buffer.get_minibatch()
  File "../src/replay_buffer.py", line 52, in get_minibatch
    batch_index = np.random.choice(buffer_range, self.batch_size, replace=False)
KeyboardInterrupt

During handling of the above exception, another exception occurred:

Traceback (most recent call last):
  File "/Users/anton/.conda/envs/reinforcement_learning/lib/python3.8/site-packages/IPython/core/interactiveshell.py", line 2045, in showtraceback
    stb = value._render_traceback_()
AttributeError: 'KeyboardInterrupt' object has no attribute '_render_traceback_'

During handling of the above exception, another exception occurred:

Traceback (most recent call last):
  File "/Users/anton/.conda/envs/reinforcement_learning/lib/python3.8/site-packages/IPython/core/ultratb.py", line 1170, in get_records
    return _fixed_getinnerframes(etb, number_of_lines_of_context, tb_offset)
  File "/Users/anton/.conda/envs/reinforcement_learning/lib/python3.8/site-packages/IPython/core/ultratb.py", line 316, in wrapped
    return f(*args, **kwargs)
  File "/Users/anton/.conda/envs/reinforcement_learning/lib/python3.8/site-packages/IPython/core/ultratb.py", line 350, in _fixed_getinnerframes
    records = fix_frame_records_filenames(inspect.getinnerframes(etb, context))
  File "/Users/anton/.conda/envs/reinforcement_learning/lib/python3.8/inspect.py", line 1503, in getinnerframes
    frameinfo = (tb.tb_frame,) + getframeinfo(tb, context)
  File "/Users/anton/.conda/envs/reinforcement_learning/lib/python3.8/inspect.py", line 1461, in getframeinfo
    filename = getsourcefile(frame) or getfile(frame)
  File "/Users/anton/.conda/envs/reinforcement_learning/lib/python3.8/inspect.py", line 708, in getsourcefile
    if getattr(getmodule(object, filename), '__loader__', None) is not None:
  File "/Users/anton/.conda/envs/reinforcement_learning/lib/python3.8/inspect.py", line 754, in getmodule
    os.path.realpath(f)] = module.__name__
  File "/Users/anton/.conda/envs/reinforcement_learning/lib/python3.8/posixpath.py", line 391, in realpath
    path, ok = _joinrealpath(filename[:0], filename, {})
  File "/Users/anton/.conda/envs/reinforcement_learning/lib/python3.8/posixpath.py", line 424, in _joinrealpath
    newpath = join(path, name)
  File "/Users/anton/.conda/envs/reinforcement_learning/lib/python3.8/posixpath.py", line 77, in join
    sep = _get_sep(a)
  File "/Users/anton/.conda/envs/reinforcement_learning/lib/python3.8/posixpath.py", line 41, in _get_sep
    def _get_sep(path):
KeyboardInterrupt
ERROR:root:Internal Python error in the inspect module.
Below is the traceback from this internal error.

Traceback (most recent call last):
  File "/Users/anton/.conda/envs/reinforcement_learning/lib/python3.8/site-packages/IPython/core/interactiveshell.py", line 3418, in run_code
    exec(code_obj, self.user_global_ns, self.user_ns)
  File "<ipython-input-7-94bfbd7604e9>", line 11, in <module>
    agent.learn()
  File "../src/agent.py", line 109, in learn
    state, action, reward, new_state, done = self.replay_buffer.get_minibatch()
  File "../src/replay_buffer.py", line 52, in get_minibatch
    batch_index = np.random.choice(buffer_range, self.batch_size, replace=False)
KeyboardInterrupt

During handling of the above exception, another exception occurred:

Traceback (most recent call last):
  File "/Users/anton/.conda/envs/reinforcement_learning/lib/python3.8/site-packages/IPython/core/interactiveshell.py", line 2045, in showtraceback
    stb = value._render_traceback_()
AttributeError: 'KeyboardInterrupt' object has no attribute '_render_traceback_'

During handling of the above exception, another exception occurred:

Traceback (most recent call last):
  File "/Users/anton/.conda/envs/reinforcement_learning/lib/python3.8/site-packages/IPython/core/interactiveshell.py", line 3338, in run_ast_nodes
    if (await self.run_code(code, result,  async_=asy)):
  File "/Users/anton/.conda/envs/reinforcement_learning/lib/python3.8/site-packages/IPython/core/interactiveshell.py", line 3435, in run_code
    self.showtraceback(running_compiled_code=True)
  File "/Users/anton/.conda/envs/reinforcement_learning/lib/python3.8/site-packages/IPython/core/interactiveshell.py", line 2047, in showtraceback
    stb = self.InteractiveTB.structured_traceback(etype,
  File "/Users/anton/.conda/envs/reinforcement_learning/lib/python3.8/site-packages/IPython/core/ultratb.py", line 1436, in structured_traceback
    return FormattedTB.structured_traceback(
  File "/Users/anton/.conda/envs/reinforcement_learning/lib/python3.8/site-packages/IPython/core/ultratb.py", line 1336, in structured_traceback
    return VerboseTB.structured_traceback(
  File "/Users/anton/.conda/envs/reinforcement_learning/lib/python3.8/site-packages/IPython/core/ultratb.py", line 1193, in structured_traceback
    formatted_exception = self.format_exception_as_a_whole(etype, evalue, etb, number_of_lines_of_context,
  File "/Users/anton/.conda/envs/reinforcement_learning/lib/python3.8/site-packages/IPython/core/ultratb.py", line 1151, in format_exception_as_a_whole
    last_unique, recursion_repeat = find_recursion(orig_etype, evalue, records)
  File "/Users/anton/.conda/envs/reinforcement_learning/lib/python3.8/site-packages/IPython/core/ultratb.py", line 451, in find_recursion
    return len(records), 0
TypeError: object of type 'NoneType' has no len()

During handling of the above exception, another exception occurred:

Traceback (most recent call last):
  File "/Users/anton/.conda/envs/reinforcement_learning/lib/python3.8/site-packages/IPython/core/interactiveshell.py", line 2045, in showtraceback
    stb = value._render_traceback_()
AttributeError: 'TypeError' object has no attribute '_render_traceback_'

During handling of the above exception, another exception occurred:

Traceback (most recent call last):
  File "/Users/anton/.conda/envs/reinforcement_learning/lib/python3.8/site-packages/IPython/core/ultratb.py", line 1170, in get_records
    return _fixed_getinnerframes(etb, number_of_lines_of_context, tb_offset)
  File "/Users/anton/.conda/envs/reinforcement_learning/lib/python3.8/site-packages/IPython/core/ultratb.py", line 316, in wrapped
    return f(*args, **kwargs)
  File "/Users/anton/.conda/envs/reinforcement_learning/lib/python3.8/site-packages/IPython/core/ultratb.py", line 350, in _fixed_getinnerframes
    records = fix_frame_records_filenames(inspect.getinnerframes(etb, context))
  File "/Users/anton/.conda/envs/reinforcement_learning/lib/python3.8/inspect.py", line 1503, in getinnerframes
    frameinfo = (tb.tb_frame,) + getframeinfo(tb, context)
  File "/Users/anton/.conda/envs/reinforcement_learning/lib/python3.8/inspect.py", line 1461, in getframeinfo
    filename = getsourcefile(frame) or getfile(frame)
  File "/Users/anton/.conda/envs/reinforcement_learning/lib/python3.8/inspect.py", line 708, in getsourcefile
    if getattr(getmodule(object, filename), '__loader__', None) is not None:
  File "/Users/anton/.conda/envs/reinforcement_learning/lib/python3.8/inspect.py", line 754, in getmodule
    os.path.realpath(f)] = module.__name__
  File "/Users/anton/.conda/envs/reinforcement_learning/lib/python3.8/posixpath.py", line 391, in realpath
    path, ok = _joinrealpath(filename[:0], filename, {})
  File "/Users/anton/.conda/envs/reinforcement_learning/lib/python3.8/posixpath.py", line 425, in _joinrealpath
    if not islink(newpath):
  File "/Users/anton/.conda/envs/reinforcement_learning/lib/python3.8/posixpath.py", line 167, in islink
    st = os.lstat(path)
KeyboardInterrupt
