  0%|          | 0/250 [00:00<?, ?it/s]  0%|          | 1/250 [00:00<00:32,  7.56it/s]  1%|          | 2/250 [00:00<00:30,  8.07it/s]  1%|          | 3/250 [00:01<02:32,  1.62it/s]  2%|▏         | 4/250 [00:02<03:53,  1.06it/s]  2%|▏         | 5/250 [00:05<06:34,  1.61s/it]  2%|▏         | 6/250 [00:08<08:06,  1.99s/it]  3%|▎         | 7/250 [00:11<09:05,  2.25s/it]  3%|▎         | 8/250 [00:13<09:09,  2.27s/it]  4%|▎         | 9/250 [00:15<09:12,  2.29s/it]  4%|▍         | 10/250 [00:20<11:53,  2.97s/it]  4%|▍         | 11/250 [00:24<13:49,  3.47s/it]  5%|▍         | 12/250 [00:26<11:10,  2.82s/it]  5%|▌         | 13/250 [00:29<11:12,  2.84s/it]  6%|▌         | 14/250 [00:31<10:04,  2.56s/it]  6%|▌         | 15/250 [00:33<09:51,  2.52s/it]  6%|▋         | 16/250 [00:36<10:51,  2.78s/it]  7%|▋         | 17/250 [00:41<12:58,  3.34s/it]  7%|▋         | 18/250 [00:44<13:02,  3.37s/it]  8%|▊         | 19/250 [00:50<15:22,  3.99s/it]  8%|▊         | 20/250 [00:56<17:45,  4.63s/it]  8%|▊         | 21/250 [01:00<16:51,  4.42s/it]  9%|▉         | 22/250 [01:03<14:49,  3.90s/it]  9%|▉         | 23/250 [01:19<29:22,  7.77s/it] 10%|▉         | 24/250 [01:22<23:37,  6.27s/it] 10%|█         | 25/250 [01:24<18:57,  5.06s/it] 10%|█         | 26/250 [01:26<15:07,  4.05s/it] 11%|█         | 27/250 [01:29<14:07,  3.80s/it] 11%|█         | 28/250 [01:34<15:24,  4.17s/it] 12%|█▏        | 29/250 [01:39<15:25,  4.19s/it] 12%|█▏        | 29/250 [01:44<13:16,  3.60s/it]
ERROR:root:Internal Python error in the inspect module.
Below is the traceback from this internal error.

Traceback (most recent call last):
  File "/Users/anton/.conda/envs/reinforcement_learning/lib/python3.8/site-packages/IPython/core/interactiveshell.py", line 3418, in run_code
    exec(code_obj, self.user_global_ns, self.user_ns)
  File "<ipython-input-7-94bfbd7604e9>", line 11, in <module>
    agent.learn()
  File "../src/agent.py", line 126, in learn
    self.critic.optimizer.apply_gradients(zip(
  File "/Users/anton/.conda/envs/reinforcement_learning/lib/python3.8/site-packages/tensorflow/python/keras/optimizer_v2/optimizer_v2.py", line 631, in apply_gradients
    return distribute_ctx.get_replica_context().merge_call(
  File "/Users/anton/.conda/envs/reinforcement_learning/lib/python3.8/site-packages/tensorflow/python/distribute/distribute_lib.py", line 2941, in merge_call
    return self._merge_call(merge_fn, args, kwargs)
  File "/Users/anton/.conda/envs/reinforcement_learning/lib/python3.8/site-packages/tensorflow/python/distribute/distribute_lib.py", line 2948, in _merge_call
    return merge_fn(self._strategy, *args, **kwargs)
  File "/Users/anton/.conda/envs/reinforcement_learning/lib/python3.8/site-packages/tensorflow/python/autograph/impl/api.py", line 572, in wrapper
    return func(*args, **kwargs)
  File "/Users/anton/.conda/envs/reinforcement_learning/lib/python3.8/site-packages/tensorflow/python/keras/optimizer_v2/optimizer_v2.py", line 682, in _distributed_apply
    update_ops.extend(distribution.extended.update(
  File "/Users/anton/.conda/envs/reinforcement_learning/lib/python3.8/site-packages/tensorflow/python/distribute/distribute_lib.py", line 2494, in update
    return self._update(var, fn, args, kwargs, group)
  File "/Users/anton/.conda/envs/reinforcement_learning/lib/python3.8/site-packages/tensorflow/python/distribute/distribute_lib.py", line 3431, in _update
    return self._update_non_slot(var, fn, (var,) + tuple(args), kwargs, group)
  File "/Users/anton/.conda/envs/reinforcement_learning/lib/python3.8/site-packages/tensorflow/python/distribute/distribute_lib.py", line 3437, in _update_non_slot
    result = fn(*args, **kwargs)
  File "/Users/anton/.conda/envs/reinforcement_learning/lib/python3.8/site-packages/tensorflow/python/autograph/impl/api.py", line 572, in wrapper
    return func(*args, **kwargs)
  File "/Users/anton/.conda/envs/reinforcement_learning/lib/python3.8/site-packages/tensorflow/python/keras/optimizer_v2/optimizer_v2.py", line 658, in apply_grad_to_update_var
    update_op = self._resource_apply_dense(grad, var, **apply_kwargs)
  File "/Users/anton/.conda/envs/reinforcement_learning/lib/python3.8/site-packages/tensorflow/python/keras/optimizer_v2/adam.py", line 175, in _resource_apply_dense
    return gen_training_ops.ResourceApplyAdam(
  File "/Users/anton/.conda/envs/reinforcement_learning/lib/python3.8/site-packages/tensorflow/python/util/tf_export.py", line 404, in wrapper
    return f(**kwargs)
  File "/Users/anton/.conda/envs/reinforcement_learning/lib/python3.8/site-packages/tensorflow/python/ops/gen_training_ops.py", line 1421, in resource_apply_adam
    _result = pywrap_tfe.TFE_Py_FastPathExecute(
KeyboardInterrupt

During handling of the above exception, another exception occurred:

Traceback (most recent call last):
  File "/Users/anton/.conda/envs/reinforcement_learning/lib/python3.8/site-packages/IPython/core/interactiveshell.py", line 2045, in showtraceback
    stb = value._render_traceback_()
AttributeError: 'KeyboardInterrupt' object has no attribute '_render_traceback_'

During handling of the above exception, another exception occurred:

Traceback (most recent call last):
  File "/Users/anton/.conda/envs/reinforcement_learning/lib/python3.8/site-packages/IPython/core/ultratb.py", line 1170, in get_records
    return _fixed_getinnerframes(etb, number_of_lines_of_context, tb_offset)
  File "/Users/anton/.conda/envs/reinforcement_learning/lib/python3.8/site-packages/IPython/core/ultratb.py", line 316, in wrapped
    return f(*args, **kwargs)
  File "/Users/anton/.conda/envs/reinforcement_learning/lib/python3.8/site-packages/IPython/core/ultratb.py", line 350, in _fixed_getinnerframes
    records = fix_frame_records_filenames(inspect.getinnerframes(etb, context))
  File "/Users/anton/.conda/envs/reinforcement_learning/lib/python3.8/inspect.py", line 1503, in getinnerframes
    frameinfo = (tb.tb_frame,) + getframeinfo(tb, context)
  File "/Users/anton/.conda/envs/reinforcement_learning/lib/python3.8/inspect.py", line 1461, in getframeinfo
    filename = getsourcefile(frame) or getfile(frame)
  File "/Users/anton/.conda/envs/reinforcement_learning/lib/python3.8/inspect.py", line 708, in getsourcefile
    if getattr(getmodule(object, filename), '__loader__', None) is not None:
  File "/Users/anton/.conda/envs/reinforcement_learning/lib/python3.8/inspect.py", line 754, in getmodule
    os.path.realpath(f)] = module.__name__
  File "/Users/anton/.conda/envs/reinforcement_learning/lib/python3.8/posixpath.py", line 391, in realpath
    path, ok = _joinrealpath(filename[:0], filename, {})
  File "/Users/anton/.conda/envs/reinforcement_learning/lib/python3.8/posixpath.py", line 424, in _joinrealpath
    newpath = join(path, name)
  File "/Users/anton/.conda/envs/reinforcement_learning/lib/python3.8/posixpath.py", line 80, in join
    if not p:
KeyboardInterrupt
ERROR:root:Internal Python error in the inspect module.
Below is the traceback from this internal error.

Traceback (most recent call last):
  File "/Users/anton/.conda/envs/reinforcement_learning/lib/python3.8/site-packages/IPython/core/interactiveshell.py", line 3418, in run_code
    exec(code_obj, self.user_global_ns, self.user_ns)
  File "<ipython-input-7-94bfbd7604e9>", line 11, in <module>
    agent.learn()
  File "../src/agent.py", line 126, in learn
    self.critic.optimizer.apply_gradients(zip(
  File "/Users/anton/.conda/envs/reinforcement_learning/lib/python3.8/site-packages/tensorflow/python/keras/optimizer_v2/optimizer_v2.py", line 631, in apply_gradients
    return distribute_ctx.get_replica_context().merge_call(
  File "/Users/anton/.conda/envs/reinforcement_learning/lib/python3.8/site-packages/tensorflow/python/distribute/distribute_lib.py", line 2941, in merge_call
    return self._merge_call(merge_fn, args, kwargs)
  File "/Users/anton/.conda/envs/reinforcement_learning/lib/python3.8/site-packages/tensorflow/python/distribute/distribute_lib.py", line 2948, in _merge_call
    return merge_fn(self._strategy, *args, **kwargs)
  File "/Users/anton/.conda/envs/reinforcement_learning/lib/python3.8/site-packages/tensorflow/python/autograph/impl/api.py", line 572, in wrapper
    return func(*args, **kwargs)
  File "/Users/anton/.conda/envs/reinforcement_learning/lib/python3.8/site-packages/tensorflow/python/keras/optimizer_v2/optimizer_v2.py", line 682, in _distributed_apply
    update_ops.extend(distribution.extended.update(
  File "/Users/anton/.conda/envs/reinforcement_learning/lib/python3.8/site-packages/tensorflow/python/distribute/distribute_lib.py", line 2494, in update
    return self._update(var, fn, args, kwargs, group)
  File "/Users/anton/.conda/envs/reinforcement_learning/lib/python3.8/site-packages/tensorflow/python/distribute/distribute_lib.py", line 3431, in _update
    return self._update_non_slot(var, fn, (var,) + tuple(args), kwargs, group)
  File "/Users/anton/.conda/envs/reinforcement_learning/lib/python3.8/site-packages/tensorflow/python/distribute/distribute_lib.py", line 3437, in _update_non_slot
    result = fn(*args, **kwargs)
  File "/Users/anton/.conda/envs/reinforcement_learning/lib/python3.8/site-packages/tensorflow/python/autograph/impl/api.py", line 572, in wrapper
    return func(*args, **kwargs)
  File "/Users/anton/.conda/envs/reinforcement_learning/lib/python3.8/site-packages/tensorflow/python/keras/optimizer_v2/optimizer_v2.py", line 658, in apply_grad_to_update_var
    update_op = self._resource_apply_dense(grad, var, **apply_kwargs)
  File "/Users/anton/.conda/envs/reinforcement_learning/lib/python3.8/site-packages/tensorflow/python/keras/optimizer_v2/adam.py", line 175, in _resource_apply_dense
    return gen_training_ops.ResourceApplyAdam(
  File "/Users/anton/.conda/envs/reinforcement_learning/lib/python3.8/site-packages/tensorflow/python/util/tf_export.py", line 404, in wrapper
    return f(**kwargs)
  File "/Users/anton/.conda/envs/reinforcement_learning/lib/python3.8/site-packages/tensorflow/python/ops/gen_training_ops.py", line 1421, in resource_apply_adam
    _result = pywrap_tfe.TFE_Py_FastPathExecute(
KeyboardInterrupt

During handling of the above exception, another exception occurred:

Traceback (most recent call last):
  File "/Users/anton/.conda/envs/reinforcement_learning/lib/python3.8/site-packages/IPython/core/interactiveshell.py", line 2045, in showtraceback
    stb = value._render_traceback_()
AttributeError: 'KeyboardInterrupt' object has no attribute '_render_traceback_'

During handling of the above exception, another exception occurred:

Traceback (most recent call last):
  File "/Users/anton/.conda/envs/reinforcement_learning/lib/python3.8/site-packages/IPython/core/interactiveshell.py", line 3338, in run_ast_nodes
    if (await self.run_code(code, result,  async_=asy)):
  File "/Users/anton/.conda/envs/reinforcement_learning/lib/python3.8/site-packages/IPython/core/interactiveshell.py", line 3435, in run_code
    self.showtraceback(running_compiled_code=True)
  File "/Users/anton/.conda/envs/reinforcement_learning/lib/python3.8/site-packages/IPython/core/interactiveshell.py", line 2047, in showtraceback
    stb = self.InteractiveTB.structured_traceback(etype,
  File "/Users/anton/.conda/envs/reinforcement_learning/lib/python3.8/site-packages/IPython/core/ultratb.py", line 1436, in structured_traceback
    return FormattedTB.structured_traceback(
  File "/Users/anton/.conda/envs/reinforcement_learning/lib/python3.8/site-packages/IPython/core/ultratb.py", line 1336, in structured_traceback
    return VerboseTB.structured_traceback(
  File "/Users/anton/.conda/envs/reinforcement_learning/lib/python3.8/site-packages/IPython/core/ultratb.py", line 1193, in structured_traceback
    formatted_exception = self.format_exception_as_a_whole(etype, evalue, etb, number_of_lines_of_context,
  File "/Users/anton/.conda/envs/reinforcement_learning/lib/python3.8/site-packages/IPython/core/ultratb.py", line 1151, in format_exception_as_a_whole
    last_unique, recursion_repeat = find_recursion(orig_etype, evalue, records)
  File "/Users/anton/.conda/envs/reinforcement_learning/lib/python3.8/site-packages/IPython/core/ultratb.py", line 451, in find_recursion
    return len(records), 0
TypeError: object of type 'NoneType' has no len()

During handling of the above exception, another exception occurred:

Traceback (most recent call last):
  File "/Users/anton/.conda/envs/reinforcement_learning/lib/python3.8/site-packages/IPython/core/interactiveshell.py", line 2045, in showtraceback
    stb = value._render_traceback_()
AttributeError: 'TypeError' object has no attribute '_render_traceback_'

During handling of the above exception, another exception occurred:

Traceback (most recent call last):
  File "/Users/anton/.conda/envs/reinforcement_learning/lib/python3.8/site-packages/IPython/core/ultratb.py", line 1170, in get_records
    return _fixed_getinnerframes(etb, number_of_lines_of_context, tb_offset)
  File "/Users/anton/.conda/envs/reinforcement_learning/lib/python3.8/site-packages/IPython/core/ultratb.py", line 316, in wrapped
    return f(*args, **kwargs)
  File "/Users/anton/.conda/envs/reinforcement_learning/lib/python3.8/site-packages/IPython/core/ultratb.py", line 350, in _fixed_getinnerframes
    records = fix_frame_records_filenames(inspect.getinnerframes(etb, context))
  File "/Users/anton/.conda/envs/reinforcement_learning/lib/python3.8/inspect.py", line 1503, in getinnerframes
    frameinfo = (tb.tb_frame,) + getframeinfo(tb, context)
  File "/Users/anton/.conda/envs/reinforcement_learning/lib/python3.8/inspect.py", line 1461, in getframeinfo
    filename = getsourcefile(frame) or getfile(frame)
  File "/Users/anton/.conda/envs/reinforcement_learning/lib/python3.8/inspect.py", line 708, in getsourcefile
    if getattr(getmodule(object, filename), '__loader__', None) is not None:
  File "/Users/anton/.conda/envs/reinforcement_learning/lib/python3.8/inspect.py", line 751, in getmodule
    f = getabsfile(module)
  File "/Users/anton/.conda/envs/reinforcement_learning/lib/python3.8/inspect.py", line 720, in getabsfile
    _filename = getsourcefile(object) or getfile(object)
  File "/Users/anton/.conda/envs/reinforcement_learning/lib/python3.8/inspect.py", line 705, in getsourcefile
    if os.path.exists(filename):
  File "/Users/anton/.conda/envs/reinforcement_learning/lib/python3.8/genericpath.py", line 19, in exists
    os.stat(path)
KeyboardInterrupt
ERROR:root:Internal Python error in the inspect module.
Below is the traceback from this internal error.

Traceback (most recent call last):
  File "/Users/anton/.conda/envs/reinforcement_learning/lib/python3.8/site-packages/IPython/core/interactiveshell.py", line 3418, in run_code
    exec(code_obj, self.user_global_ns, self.user_ns)
  File "<ipython-input-7-94bfbd7604e9>", line 11, in <module>
    agent.learn()
  File "../src/agent.py", line 126, in learn
    self.critic.optimizer.apply_gradients(zip(
  File "/Users/anton/.conda/envs/reinforcement_learning/lib/python3.8/site-packages/tensorflow/python/keras/optimizer_v2/optimizer_v2.py", line 631, in apply_gradients
    return distribute_ctx.get_replica_context().merge_call(
  File "/Users/anton/.conda/envs/reinforcement_learning/lib/python3.8/site-packages/tensorflow/python/distribute/distribute_lib.py", line 2941, in merge_call
    return self._merge_call(merge_fn, args, kwargs)
  File "/Users/anton/.conda/envs/reinforcement_learning/lib/python3.8/site-packages/tensorflow/python/distribute/distribute_lib.py", line 2948, in _merge_call
    return merge_fn(self._strategy, *args, **kwargs)
  File "/Users/anton/.conda/envs/reinforcement_learning/lib/python3.8/site-packages/tensorflow/python/autograph/impl/api.py", line 572, in wrapper
    return func(*args, **kwargs)
  File "/Users/anton/.conda/envs/reinforcement_learning/lib/python3.8/site-packages/tensorflow/python/keras/optimizer_v2/optimizer_v2.py", line 682, in _distributed_apply
    update_ops.extend(distribution.extended.update(
  File "/Users/anton/.conda/envs/reinforcement_learning/lib/python3.8/site-packages/tensorflow/python/distribute/distribute_lib.py", line 2494, in update
    return self._update(var, fn, args, kwargs, group)
  File "/Users/anton/.conda/envs/reinforcement_learning/lib/python3.8/site-packages/tensorflow/python/distribute/distribute_lib.py", line 3431, in _update
    return self._update_non_slot(var, fn, (var,) + tuple(args), kwargs, group)
  File "/Users/anton/.conda/envs/reinforcement_learning/lib/python3.8/site-packages/tensorflow/python/distribute/distribute_lib.py", line 3437, in _update_non_slot
    result = fn(*args, **kwargs)
  File "/Users/anton/.conda/envs/reinforcement_learning/lib/python3.8/site-packages/tensorflow/python/autograph/impl/api.py", line 572, in wrapper
    return func(*args, **kwargs)
  File "/Users/anton/.conda/envs/reinforcement_learning/lib/python3.8/site-packages/tensorflow/python/keras/optimizer_v2/optimizer_v2.py", line 658, in apply_grad_to_update_var
    update_op = self._resource_apply_dense(grad, var, **apply_kwargs)
  File "/Users/anton/.conda/envs/reinforcement_learning/lib/python3.8/site-packages/tensorflow/python/keras/optimizer_v2/adam.py", line 175, in _resource_apply_dense
    return gen_training_ops.ResourceApplyAdam(
  File "/Users/anton/.conda/envs/reinforcement_learning/lib/python3.8/site-packages/tensorflow/python/util/tf_export.py", line 404, in wrapper
    return f(**kwargs)
  File "/Users/anton/.conda/envs/reinforcement_learning/lib/python3.8/site-packages/tensorflow/python/ops/gen_training_ops.py", line 1421, in resource_apply_adam
    _result = pywrap_tfe.TFE_Py_FastPathExecute(
KeyboardInterrupt

During handling of the above exception, another exception occurred:

Traceback (most recent call last):
  File "/Users/anton/.conda/envs/reinforcement_learning/lib/python3.8/site-packages/IPython/core/interactiveshell.py", line 2045, in showtraceback
    stb = value._render_traceback_()
AttributeError: 'KeyboardInterrupt' object has no attribute '_render_traceback_'

During handling of the above exception, another exception occurred:

Traceback (most recent call last):
  File "/Users/anton/.conda/envs/reinforcement_learning/lib/python3.8/site-packages/IPython/core/interactiveshell.py", line 3338, in run_ast_nodes
    if (await self.run_code(code, result,  async_=asy)):
  File "/Users/anton/.conda/envs/reinforcement_learning/lib/python3.8/site-packages/IPython/core/interactiveshell.py", line 3435, in run_code
    self.showtraceback(running_compiled_code=True)
  File "/Users/anton/.conda/envs/reinforcement_learning/lib/python3.8/site-packages/IPython/core/interactiveshell.py", line 2047, in showtraceback
    stb = self.InteractiveTB.structured_traceback(etype,
  File "/Users/anton/.conda/envs/reinforcement_learning/lib/python3.8/site-packages/IPython/core/ultratb.py", line 1436, in structured_traceback
    return FormattedTB.structured_traceback(
  File "/Users/anton/.conda/envs/reinforcement_learning/lib/python3.8/site-packages/IPython/core/ultratb.py", line 1336, in structured_traceback
    return VerboseTB.structured_traceback(
  File "/Users/anton/.conda/envs/reinforcement_learning/lib/python3.8/site-packages/IPython/core/ultratb.py", line 1193, in structured_traceback
    formatted_exception = self.format_exception_as_a_whole(etype, evalue, etb, number_of_lines_of_context,
  File "/Users/anton/.conda/envs/reinforcement_learning/lib/python3.8/site-packages/IPython/core/ultratb.py", line 1151, in format_exception_as_a_whole
    last_unique, recursion_repeat = find_recursion(orig_etype, evalue, records)
  File "/Users/anton/.conda/envs/reinforcement_learning/lib/python3.8/site-packages/IPython/core/ultratb.py", line 451, in find_recursion
    return len(records), 0
TypeError: object of type 'NoneType' has no len()

During handling of the above exception, another exception occurred:

Traceback (most recent call last):
  File "/Users/anton/.conda/envs/reinforcement_learning/lib/python3.8/site-packages/IPython/core/interactiveshell.py", line 2045, in showtraceback
    stb = value._render_traceback_()
AttributeError: 'TypeError' object has no attribute '_render_traceback_'

During handling of the above exception, another exception occurred:

Traceback (most recent call last):
  File "/Users/anton/.conda/envs/reinforcement_learning/lib/python3.8/site-packages/IPython/core/interactiveshell.py", line 2923, in _run_cell
    return runner(coro)
  File "/Users/anton/.conda/envs/reinforcement_learning/lib/python3.8/site-packages/IPython/core/async_helpers.py", line 68, in _pseudo_sync_runner
    coro.send(None)
  File "/Users/anton/.conda/envs/reinforcement_learning/lib/python3.8/site-packages/IPython/core/interactiveshell.py", line 3146, in run_cell_async
    has_raised = await self.run_ast_nodes(code_ast.body, cell_name,
  File "/Users/anton/.conda/envs/reinforcement_learning/lib/python3.8/site-packages/IPython/core/interactiveshell.py", line 3357, in run_ast_nodes
    self.showtraceback()
  File "/Users/anton/.conda/envs/reinforcement_learning/lib/python3.8/site-packages/IPython/core/interactiveshell.py", line 2047, in showtraceback
    stb = self.InteractiveTB.structured_traceback(etype,
  File "/Users/anton/.conda/envs/reinforcement_learning/lib/python3.8/site-packages/IPython/core/ultratb.py", line 1436, in structured_traceback
    return FormattedTB.structured_traceback(
  File "/Users/anton/.conda/envs/reinforcement_learning/lib/python3.8/site-packages/IPython/core/ultratb.py", line 1336, in structured_traceback
    return VerboseTB.structured_traceback(
  File "/Users/anton/.conda/envs/reinforcement_learning/lib/python3.8/site-packages/IPython/core/ultratb.py", line 1211, in structured_traceback
    formatted_exceptions += self.format_exception_as_a_whole(etype, evalue, etb, lines_of_context,
  File "/Users/anton/.conda/envs/reinforcement_learning/lib/python3.8/site-packages/IPython/core/ultratb.py", line 1151, in format_exception_as_a_whole
    last_unique, recursion_repeat = find_recursion(orig_etype, evalue, records)
  File "/Users/anton/.conda/envs/reinforcement_learning/lib/python3.8/site-packages/IPython/core/ultratb.py", line 451, in find_recursion
    return len(records), 0
TypeError: object of type 'NoneType' has no len()

During handling of the above exception, another exception occurred:

Traceback (most recent call last):
  File "/Users/anton/.conda/envs/reinforcement_learning/lib/python3.8/site-packages/IPython/core/interactiveshell.py", line 2045, in showtraceback
    stb = value._render_traceback_()
AttributeError: 'TypeError' object has no attribute '_render_traceback_'

During handling of the above exception, another exception occurred:

Traceback (most recent call last):
  File "/Users/anton/.conda/envs/reinforcement_learning/lib/python3.8/site-packages/IPython/core/ultratb.py", line 1170, in get_records
    return _fixed_getinnerframes(etb, number_of_lines_of_context, tb_offset)
  File "/Users/anton/.conda/envs/reinforcement_learning/lib/python3.8/site-packages/IPython/core/ultratb.py", line 316, in wrapped
    return f(*args, **kwargs)
  File "/Users/anton/.conda/envs/reinforcement_learning/lib/python3.8/site-packages/IPython/core/ultratb.py", line 350, in _fixed_getinnerframes
    records = fix_frame_records_filenames(inspect.getinnerframes(etb, context))
  File "/Users/anton/.conda/envs/reinforcement_learning/lib/python3.8/inspect.py", line 1503, in getinnerframes
    frameinfo = (tb.tb_frame,) + getframeinfo(tb, context)
  File "/Users/anton/.conda/envs/reinforcement_learning/lib/python3.8/inspect.py", line 1461, in getframeinfo
    filename = getsourcefile(frame) or getfile(frame)
  File "/Users/anton/.conda/envs/reinforcement_learning/lib/python3.8/inspect.py", line 708, in getsourcefile
    if getattr(getmodule(object, filename), '__loader__', None) is not None:
  File "/Users/anton/.conda/envs/reinforcement_learning/lib/python3.8/inspect.py", line 754, in getmodule
    os.path.realpath(f)] = module.__name__
  File "/Users/anton/.conda/envs/reinforcement_learning/lib/python3.8/posixpath.py", line 391, in realpath
    path, ok = _joinrealpath(filename[:0], filename, {})
  File "/Users/anton/.conda/envs/reinforcement_learning/lib/python3.8/posixpath.py", line 424, in _joinrealpath
    newpath = join(path, name)
  File "/Users/anton/.conda/envs/reinforcement_learning/lib/python3.8/posixpath.py", line 82, in join
    for b in map(os.fspath, p):
KeyboardInterrupt
