/Users/anton/.conda/envs/reinforcement_learning/lib/python3.8/site-packages/gym/logger.py:30: UserWarning: [33mWARN: Box bound precision lowered by casting to float32[0m
  warnings.warn(colorize('%s: %s'%('WARN', msg % args), 'yellow'))
  0%|          | 0/100000 [00:00<?, ?it/s]  0%|          | 1/100000 [00:00<4:35:38,  6.05it/s]  0%|          | 2/100000 [00:00<3:41:39,  7.52it/s]  0%|          | 3/100000 [00:00<3:45:15,  7.40it/s]  0%|          | 4/100000 [00:00<3:34:22,  7.77it/s]  0%|          | 5/100000 [00:00<4:06:34,  6.76it/s]  0%|          | 6/100000 [00:01<13:36:07,  2.04it/s]  0%|          | 7/100000 [00:02<17:30:51,  1.59it/s]  0%|          | 8/100000 [00:03<20:06:46,  1.38it/s]  0%|          | 9/100000 [00:04<21:23:06,  1.30it/s]  0%|          | 10/100000 [00:05<21:49:14,  1.27it/s]  0%|          | 11/100000 [00:06<24:49:22,  1.12it/s]  0%|          | 12/100000 [00:07<24:34:19,  1.13it/s]  0%|          | 13/100000 [00:08<24:23:55,  1.14it/s]  0%|          | 14/100000 [00:09<24:22:03,  1.14it/s]  0%|          | 15/100000 [00:10<24:52:31,  1.12it/s]  0%|          | 16/100000 [00:10<24:22:13,  1.14it/s]  0%|          | 17/100000 [00:11<24:15:59,  1.14it/s]  0%|          | 18/100000 [00:12<26:03:44,  1.07it/s]  0%|          | 19/100000 [00:13<26:36:55,  1.04it/s]  0%|          | 20/100000 [00:14<26:45:06,  1.04it/s]  0%|          | 21/100000 [00:15<26:05:19,  1.06it/s]  0%|          | 22/100000 [00:16<26:24:56,  1.05it/s]  0%|          | 23/100000 [00:17<26:27:37,  1.05it/s]  0%|          | 24/100000 [00:18<26:29:41,  1.05it/s]  0%|          | 25/100000 [00:19<29:20:03,  1.06s/it]  0%|          | 26/100000 [00:21<33:18:45,  1.20s/it]  0%|          | 27/100000 [00:22<30:44:09,  1.11s/it]  0%|          | 27/100000 [00:22<23:01:48,  1.21it/s]
ERROR:root:Internal Python error in the inspect module.
Below is the traceback from this internal error.

Traceback (most recent call last):
  File "/Users/anton/.conda/envs/reinforcement_learning/lib/python3.8/site-packages/IPython/core/interactiveshell.py", line 3418, in run_code
    exec(code_obj, self.user_global_ns, self.user_ns)
  File "<ipython-input-7-8f485f7f2afa>", line 11, in <module>
    agent.learn()
  File "../src/agent.py", line 131, in learn
    self.critic_0.optimizer.apply_gradients(zip(critic_0_network_gradient, self.critic_0.trainable_variables))
  File "/Users/anton/.conda/envs/reinforcement_learning/lib/python3.8/site-packages/tensorflow/python/keras/optimizer_v2/optimizer_v2.py", line 631, in apply_gradients
    return distribute_ctx.get_replica_context().merge_call(
  File "/Users/anton/.conda/envs/reinforcement_learning/lib/python3.8/site-packages/tensorflow/python/distribute/distribute_lib.py", line 2941, in merge_call
    return self._merge_call(merge_fn, args, kwargs)
  File "/Users/anton/.conda/envs/reinforcement_learning/lib/python3.8/site-packages/tensorflow/python/distribute/distribute_lib.py", line 2948, in _merge_call
    return merge_fn(self._strategy, *args, **kwargs)
  File "/Users/anton/.conda/envs/reinforcement_learning/lib/python3.8/site-packages/tensorflow/python/autograph/impl/api.py", line 572, in wrapper
    return func(*args, **kwargs)
  File "/Users/anton/.conda/envs/reinforcement_learning/lib/python3.8/site-packages/tensorflow/python/keras/optimizer_v2/optimizer_v2.py", line 682, in _distributed_apply
    update_ops.extend(distribution.extended.update(
  File "/Users/anton/.conda/envs/reinforcement_learning/lib/python3.8/site-packages/tensorflow/python/distribute/distribute_lib.py", line 2493, in update
    with self._container_strategy().scope():
  File "/Users/anton/.conda/envs/reinforcement_learning/lib/python3.8/site-packages/tensorflow/python/distribute/distribute_lib.py", line 3340, in __enter__
    if distribution_strategy_context.has_strategy():
  File "/Users/anton/.conda/envs/reinforcement_learning/lib/python3.8/site-packages/tensorflow/python/distribute/distribution_strategy_context.py", line 200, in has_strategy
    @tf_export("distribute.has_strategy")
KeyboardInterrupt

During handling of the above exception, another exception occurred:

Traceback (most recent call last):
  File "/Users/anton/.conda/envs/reinforcement_learning/lib/python3.8/site-packages/IPython/core/interactiveshell.py", line 2045, in showtraceback
    stb = value._render_traceback_()
AttributeError: 'KeyboardInterrupt' object has no attribute '_render_traceback_'

During handling of the above exception, another exception occurred:

Traceback (most recent call last):
  File "/Users/anton/.conda/envs/reinforcement_learning/lib/python3.8/site-packages/IPython/core/ultratb.py", line 1170, in get_records
    return _fixed_getinnerframes(etb, number_of_lines_of_context, tb_offset)
  File "/Users/anton/.conda/envs/reinforcement_learning/lib/python3.8/site-packages/IPython/core/ultratb.py", line 316, in wrapped
    return f(*args, **kwargs)
  File "/Users/anton/.conda/envs/reinforcement_learning/lib/python3.8/site-packages/IPython/core/ultratb.py", line 350, in _fixed_getinnerframes
    records = fix_frame_records_filenames(inspect.getinnerframes(etb, context))
  File "/Users/anton/.conda/envs/reinforcement_learning/lib/python3.8/inspect.py", line 1503, in getinnerframes
    frameinfo = (tb.tb_frame,) + getframeinfo(tb, context)
  File "/Users/anton/.conda/envs/reinforcement_learning/lib/python3.8/inspect.py", line 1461, in getframeinfo
    filename = getsourcefile(frame) or getfile(frame)
  File "/Users/anton/.conda/envs/reinforcement_learning/lib/python3.8/inspect.py", line 708, in getsourcefile
    if getattr(getmodule(object, filename), '__loader__', None) is not None:
  File "/Users/anton/.conda/envs/reinforcement_learning/lib/python3.8/inspect.py", line 754, in getmodule
    os.path.realpath(f)] = module.__name__
  File "/Users/anton/.conda/envs/reinforcement_learning/lib/python3.8/posixpath.py", line 391, in realpath
    path, ok = _joinrealpath(filename[:0], filename, {})
  File "/Users/anton/.conda/envs/reinforcement_learning/lib/python3.8/posixpath.py", line 424, in _joinrealpath
    newpath = join(path, name)
  File "/Users/anton/.conda/envs/reinforcement_learning/lib/python3.8/posixpath.py", line 88, in join
    path += sep + b
KeyboardInterrupt
ERROR:root:Internal Python error in the inspect module.
Below is the traceback from this internal error.

Traceback (most recent call last):
  File "/Users/anton/.conda/envs/reinforcement_learning/lib/python3.8/site-packages/IPython/core/interactiveshell.py", line 3418, in run_code
    exec(code_obj, self.user_global_ns, self.user_ns)
  File "<ipython-input-7-8f485f7f2afa>", line 11, in <module>
    agent.learn()
  File "../src/agent.py", line 131, in learn
    self.critic_0.optimizer.apply_gradients(zip(critic_0_network_gradient, self.critic_0.trainable_variables))
  File "/Users/anton/.conda/envs/reinforcement_learning/lib/python3.8/site-packages/tensorflow/python/keras/optimizer_v2/optimizer_v2.py", line 631, in apply_gradients
    return distribute_ctx.get_replica_context().merge_call(
  File "/Users/anton/.conda/envs/reinforcement_learning/lib/python3.8/site-packages/tensorflow/python/distribute/distribute_lib.py", line 2941, in merge_call
    return self._merge_call(merge_fn, args, kwargs)
  File "/Users/anton/.conda/envs/reinforcement_learning/lib/python3.8/site-packages/tensorflow/python/distribute/distribute_lib.py", line 2948, in _merge_call
    return merge_fn(self._strategy, *args, **kwargs)
  File "/Users/anton/.conda/envs/reinforcement_learning/lib/python3.8/site-packages/tensorflow/python/autograph/impl/api.py", line 572, in wrapper
    return func(*args, **kwargs)
  File "/Users/anton/.conda/envs/reinforcement_learning/lib/python3.8/site-packages/tensorflow/python/keras/optimizer_v2/optimizer_v2.py", line 682, in _distributed_apply
    update_ops.extend(distribution.extended.update(
  File "/Users/anton/.conda/envs/reinforcement_learning/lib/python3.8/site-packages/tensorflow/python/distribute/distribute_lib.py", line 2493, in update
    with self._container_strategy().scope():
  File "/Users/anton/.conda/envs/reinforcement_learning/lib/python3.8/site-packages/tensorflow/python/distribute/distribute_lib.py", line 3340, in __enter__
    if distribution_strategy_context.has_strategy():
  File "/Users/anton/.conda/envs/reinforcement_learning/lib/python3.8/site-packages/tensorflow/python/distribute/distribution_strategy_context.py", line 200, in has_strategy
    @tf_export("distribute.has_strategy")
KeyboardInterrupt

During handling of the above exception, another exception occurred:

Traceback (most recent call last):
  File "/Users/anton/.conda/envs/reinforcement_learning/lib/python3.8/site-packages/IPython/core/interactiveshell.py", line 2045, in showtraceback
    stb = value._render_traceback_()
AttributeError: 'KeyboardInterrupt' object has no attribute '_render_traceback_'

During handling of the above exception, another exception occurred:

Traceback (most recent call last):
  File "/Users/anton/.conda/envs/reinforcement_learning/lib/python3.8/site-packages/IPython/core/interactiveshell.py", line 3338, in run_ast_nodes
    if (await self.run_code(code, result,  async_=asy)):
  File "/Users/anton/.conda/envs/reinforcement_learning/lib/python3.8/site-packages/IPython/core/interactiveshell.py", line 3435, in run_code
    self.showtraceback(running_compiled_code=True)
  File "/Users/anton/.conda/envs/reinforcement_learning/lib/python3.8/site-packages/IPython/core/interactiveshell.py", line 2047, in showtraceback
    stb = self.InteractiveTB.structured_traceback(etype,
  File "/Users/anton/.conda/envs/reinforcement_learning/lib/python3.8/site-packages/IPython/core/ultratb.py", line 1436, in structured_traceback
    return FormattedTB.structured_traceback(
  File "/Users/anton/.conda/envs/reinforcement_learning/lib/python3.8/site-packages/IPython/core/ultratb.py", line 1336, in structured_traceback
    return VerboseTB.structured_traceback(
  File "/Users/anton/.conda/envs/reinforcement_learning/lib/python3.8/site-packages/IPython/core/ultratb.py", line 1193, in structured_traceback
    formatted_exception = self.format_exception_as_a_whole(etype, evalue, etb, number_of_lines_of_context,
  File "/Users/anton/.conda/envs/reinforcement_learning/lib/python3.8/site-packages/IPython/core/ultratb.py", line 1151, in format_exception_as_a_whole
    last_unique, recursion_repeat = find_recursion(orig_etype, evalue, records)
  File "/Users/anton/.conda/envs/reinforcement_learning/lib/python3.8/site-packages/IPython/core/ultratb.py", line 451, in find_recursion
    return len(records), 0
TypeError: object of type 'NoneType' has no len()

During handling of the above exception, another exception occurred:

Traceback (most recent call last):
  File "/Users/anton/.conda/envs/reinforcement_learning/lib/python3.8/site-packages/IPython/core/interactiveshell.py", line 2045, in showtraceback
    stb = value._render_traceback_()
AttributeError: 'TypeError' object has no attribute '_render_traceback_'

During handling of the above exception, another exception occurred:

Traceback (most recent call last):
  File "/Users/anton/.conda/envs/reinforcement_learning/lib/python3.8/site-packages/IPython/core/ultratb.py", line 1170, in get_records
    return _fixed_getinnerframes(etb, number_of_lines_of_context, tb_offset)
  File "/Users/anton/.conda/envs/reinforcement_learning/lib/python3.8/site-packages/IPython/core/ultratb.py", line 316, in wrapped
    return f(*args, **kwargs)
  File "/Users/anton/.conda/envs/reinforcement_learning/lib/python3.8/site-packages/IPython/core/ultratb.py", line 350, in _fixed_getinnerframes
    records = fix_frame_records_filenames(inspect.getinnerframes(etb, context))
  File "/Users/anton/.conda/envs/reinforcement_learning/lib/python3.8/inspect.py", line 1503, in getinnerframes
    frameinfo = (tb.tb_frame,) + getframeinfo(tb, context)
  File "/Users/anton/.conda/envs/reinforcement_learning/lib/python3.8/inspect.py", line 1461, in getframeinfo
    filename = getsourcefile(frame) or getfile(frame)
  File "/Users/anton/.conda/envs/reinforcement_learning/lib/python3.8/inspect.py", line 708, in getsourcefile
    if getattr(getmodule(object, filename), '__loader__', None) is not None:
  File "/Users/anton/.conda/envs/reinforcement_learning/lib/python3.8/inspect.py", line 754, in getmodule
    os.path.realpath(f)] = module.__name__
  File "/Users/anton/.conda/envs/reinforcement_learning/lib/python3.8/posixpath.py", line 391, in realpath
    path, ok = _joinrealpath(filename[:0], filename, {})
  File "/Users/anton/.conda/envs/reinforcement_learning/lib/python3.8/posixpath.py", line 425, in _joinrealpath
    if not islink(newpath):
  File "/Users/anton/.conda/envs/reinforcement_learning/lib/python3.8/posixpath.py", line 167, in islink
    st = os.lstat(path)
KeyboardInterrupt
